print('print exception for catch')